Workbook

Sheet Dashboard
B1: DATA KEUANGAN HAPIA JEMBER
B2: ="Tahun Buku "&Pengaturan!$C$6&" • "&Pengaturan!$C$5&" • Dikelola oleh Bendahara: "&Pengaturan!$C$9 -> Tahun Buku 2026 • HAPIA Jember • Dikelola oleh Bendahara: Nama Bendahara
B4: ="Posisi per "&INDEX(Pengaturan!$H$19:$H$30,MONTH(Pengaturan!$C$14))&" "&YEAR(Pengaturan!$C$14)&" • Ringkasan otomatis dari seluruh sheet" -> Posisi per Oktober 2026 • Ringkasan otomatis dari seluruh sheet
B6: TOTAL SALDO (KAS + BANK) | E6: TOTAL PEMASUKAN | H6: TOTAL PENGELUARAN | K6: SURPLUS / (DEFISIT)
B7: =Pengaturan!$C$10+Pengaturan!$C$11+SUM(Transaksi!$J$6:$J$505)-SUM(Transaksi!$K$6:$K$505) -> 20313000 | E7: =SUM(Transaksi!$J$6:$J$505) -> 20843000 | H7: =SUM(Transaksi!$K$6:$K$505) -> 30530000 | K7: =SUM(Transaksi!$J$6:$J$505)-SUM(Transaksi!$K$6:$K$505) -> -9687000
B10: SALDO KAS TUNAI | E10: SALDO REKENING BANK | H10: TOTAL EVENT | K10: JUMLAH TRANSAKSI
B11: =Pengaturan!$C$10+SUMIFS(Transaksi!$J$6:$J$505,Transaksi!$G$6:$G$505,Pengaturan!$F$19)-SUMIFS(Transaksi!$K$6:$K$505,Transaksi!$G$6:$G$505,Pengaturan!$F$19) -> 4120000 | E11: =Pengaturan!$C$11+SUMIFS(Transaksi!$J$6:$J$505,Transaksi!$G$6:$G$505,Pengaturan!$F$20)-SUMIFS(Transaksi!$K$6:$K$505,Transaksi!$G$6:$G$505,Pengaturan!$F$20) -> 16193000 | H11: =COUNTA(Event!$C$9:$C$28) -> 8 | K11: =COUNT(Transaksi!$C$6:$C$505) -> 39
B14: ▌ PEMASUKAN vs PENGELUARAN PER BULAN | H14: ▌ PERKEMBANGAN SALDO
B30: ▌ ANGGARAN vs REALISASI PENGELUARAN | H30: ▌ 5 TRANSAKSI TERAKHIR
H31: Tanggal | I31: Uraian | L31: Jenis | M31: Jumlah (Rp)
H32: =IF(COUNT(Transaksi!$C$6:$C$505)<1,"",INDEX(Transaksi!$C$6:$C$505,COUNT(Transaksi!$C$6:$C$505)-0)) -> 46310 | I32: =IF(COUNT(Transaksi!$C$6:$C$505)<1,"",INDEX(Transaksi!$H$6:$H$505,COUNT(Transaksi!$C$6:$C$505)-0)) -> Transport survei lokasi kegiatan | L32: =IF(COUNT(Transaksi!$C$6:$C$505)<1,"",INDEX(Transaksi!$E$6:$E$505,COUNT(Transaksi!$C$6:$C$505)-0)) -> Pengeluaran | M32: =IF(COUNT(Transaksi!$C$6:$C$505)<1,"",INDEX(Transaksi!$I$6:$I$505,COUNT(Transaksi!$C$6:$C$505)-0)) -> 250000
H33: =IF(COUNT(Transaksi!$C$6:$C$505)<2,"",INDEX(Transaksi!$C$6:$C$505,COUNT(Transaksi!$C$6:$C$505)-1)) -> 46310 | I33: =IF(COUNT(Transaksi!$C$6:$C$505)<2,"",INDEX(Transaksi!$H$6:$H$505,COUNT(Transaksi!$C$6:$C$505)-1)) -> Biaya administrasi bank Oktober | L33: =IF(COUNT(Transaksi!$C$6:$C$505)<2,"",INDEX(Transaksi!$E$6:$E$505,COUNT(Transaksi!$C$6:$C$505)-1)) -> Pengeluaran | M33: =IF(COUNT(Transaksi!$C$6:$C$505)<2,"",INDEX(Transaksi!$I$6:$I$505,COUNT(Transaksi!$C$6:$C$505)-1)) -> 15000
H34: =IF(COUNT(Transaksi!$C$6:$C$505)<3,"",INDEX(Transaksi!$C$6:$C$505,COUNT(Transaksi!$C$6:$C$505)-2)) -> 46307 | I34: =IF(COUNT(Transaksi!$C$6:$C$505)<3,"",INDEX(Transaksi!$H$6:$H$505,COUNT(Transaksi!$C$6:$C$505)-2)) -> Konsumsi rapat evaluasi | L34: =IF(COUNT(Transaksi!$C$6:$C$505)<3,"",INDEX(Transaksi!$E$6:$E$505,COUNT(Transaksi!$C$6:$C$505)-2)) -> Pengeluaran | M34: =IF(COUNT(Transaksi!$C$6:$C$505)<3,"",INDEX(Transaksi!$I$6:$I$505,COUNT(Transaksi!$C$6:$C$505)-2)) -> 500000
H35: =IF(COUNT(Transaksi!$C$6:$C$505)<4,"",INDEX(Transaksi!$C$6:$C$505,COUNT(Transaksi!$C$6:$C$505)-3)) -> 46305 | I35: =IF(COUNT(Transaksi!$C$6:$C$505)<4,"",INDEX(Transaksi!$H$6:$H$505,COUNT(Transaksi!$C$6:$C$505)-3)) -> Fotokopi dan materai | L35: =IF(COUNT(Transaksi!$C$6:$C$505)<4,"",INDEX(Transaksi!$E$6:$E$505,COUNT(Transaksi!$C$6:$C$505)-3)) -> Pengeluaran | M35: =IF(COUNT(Transaksi!$C$6:$C$505)<4,"",INDEX(Transaksi!$I$6:$I$505,COUNT(Transaksi!$C$6:$C$505)-3)) -> 180000
H36: =IF(COUNT(Transaksi!$C$6:$C$505)<5,"",INDEX(Transaksi!$C$6:$C$505,COUNT(Transaksi!$C$6:$C$505)-4)) -> 46300 | I36: =IF(COUNT(Transaksi!$C$6:$C$505)<5,"",INDEX(Transaksi!$H$6:$H$505,COUNT(Transaksi!$C$6:$C$505)-4)) -> Sewa sekretariat triwulan IV | L36: =IF(COUNT(Transaksi!$C$6:$C$505)<5,"",INDEX(Transaksi!$E$6:$E$505,COUNT(Transaksi!$C$6:$C$505)-4)) -> Pengeluaran | M36: =IF(COUNT(Transaksi!$C$6:$C$505)<5,"",INDEX(Transaksi!$I$6:$I$505,COUNT(Transaksi!$C$6:$C$505)-4)) -> 1500000
H38: STATUS ANGGARAN PENGELUARAN
H39: Aman | L39: =COUNTIF(Anggaran!$H$19:$H$30,"Aman")&" kategori" -> 6 kategori
H40: Waspada | L40: =COUNTIF(Anggaran!$H$19:$H$30,"Waspada")&" kategori" -> 3 kategori
H41: Melebihi anggaran | L41: =COUNTIF(Anggaran!$H$19:$H$30,"Melebihi")&" kategori" -> 1 kategori
H43: Hasil bersih seluruh event: | L43: =Event!K29 -> 4550000
H44: Data pada file ini adalah CONTOH — hapus & ganti dengan data asli (lihat sheet Panduan).
B50: ▌ KEUANGAN PER EVENT (Pemasukan vs Pengeluaran)
B68: Grafik menampilkan 12 event pertama pada sheet Event.

Sheet Transaksi
B1: DATA KEUANGAN HAPIA JEMBER
B2: ="Tahun Buku "&Pengaturan!$C$6&" • "&Pengaturan!$C$5&" • Dikelola oleh Bendahara: "&Pengaturan!$C$9 -> Tahun Buku 2026 • HAPIA Jember • Dikelola oleh Bendahara: Nama Bendahara
B4: JURNAL TRANSAKSI — isi baris berikutnya di bawah data terakhir. Sel putih biru = input · sel krem = otomatis. | I4: TOTAL ▶ | J4: =SUM(J6:J505) -> 20843000 | K4: =SUM(K6:K505) -> 30530000
B5: No | C5: Tanggal | D5: No. Bukti | E5: Jenis | F5: Kategori | G5: Akun | H5: Uraian Transaksi | I5: Jumlah (Rp) | J5: Pemasukan (Rp) | K5: Pengeluaran (Rp) | L5: Bulan | M5: Penanggung Jawab | N5: Keterangan | O5: Event (opsional)
B6: =IF(C6="","",ROW()-5) -> 1 | C6: 46027 | D6: KK-001 | E6: Pengeluaran | F6: Sewa & Utilitas | G6: Bank | H6: Sewa sekretariat triwulan I | I6: 1500000 | J6: =IF(OR(C6="",I6=""),"",IF(E6=Pengaturan!$J$19,I6,0)) -> 0 | K6: =IF(OR(C6="",I6=""),"",IF(E6=Pengaturan!$J$20,I6,0)) -> 1500000 | L6: =IF(C6="","",MONTH(C6)) -> 1 | M6: Bendahara
B7: =IF(C7="","",ROW()-5) -> 2 | C7: 46032 | D7: KM-001 | E7: Pemasukan | F7: Donasi | G7: Bank | H7: Donasi Bapak H. Santoso untuk seminar | I7: 2000000 | J7: =IF(OR(C7="",I7=""),"",IF(E7=Pengaturan!$J$19,I7,0)) -> 2000000 | K7: =IF(OR(C7="",I7=""),"",IF(E7=Pengaturan!$J$20,I7,0)) -> 0 | L7: =IF(C7="","",MONTH(C7)) -> 1 | M7: Ketua | N7: Contoh data | O7: Seminar Nasional Pendidikan
B8: =IF(C8="","",ROW()-5) -> 3 | C8: 46034 | D8: KK-002 | E8: Pengeluaran | F8: ATK & Percetakan | G8: Kas Tunai | H8: Cetak kartu anggota | I8: 450000 | J8: =IF(OR(C8="",I8=""),"",IF(E8=Pengaturan!$J$19,I8,0)) -> 0 | K8: =IF(OR(C8="",I8=""),"",IF(E8=Pengaturan!$J$20,I8,0)) -> 450000 | L8: =IF(C8="","",MONTH(C8)) -> 1 | M8: Sekretaris
B9: =IF(C9="","",ROW()-5) -> 4 | C9: 46047 | D9: KK-003 | E9: Pengeluaran | F9: Konsumsi | G9: Kas Tunai | H9: Konsumsi rapat kerja awal tahun | I9: 600000 | J9: =IF(OR(C9="",I9=""),"",IF(E9=Pengaturan!$J$19,I9,0)) -> 0 | K9: =IF(OR(C9="",I9=""),"",IF(E9=Pengaturan!$J$20,I9,0)) -> 600000 | L9: =IF(C9="","",MONTH(C9)) -> 1 | M9: Seksi Konsumsi | O9: Rapat Kerja Awal Tahun
B10: =IF(C10="","",ROW()-5) -> 5 | C10: 46050 | D10: KK-004 | E10: Pengeluaran | F10: Administrasi Bank | G10: Bank | H10: Biaya administrasi bank Januari | I10: 15000 | J10: =IF(OR(C10="",I10=""),"",IF(E10=Pengaturan!$J$19,I10,0)) -> 0 | K10: =IF(OR(C10="",I10=""),"",IF(E10=Pengaturan!$J$20,I10,0)) -> 15000 | L10: =IF(C10="","",MONTH(C10)) -> 1 | M10: Bendahara | N10: Potongan otomatis
B11: =IF(C11="","",ROW()-5) -> 6 | C11: 46065 | D11: KM-002 | E11: Pemasukan | F11: Pendaftaran / Tiket Event | G11: Bank | H11: Pendaftaran peserta seminar | I11: 3500000 | J11: =IF(OR(C11="",I11=""),"",IF(E11=Pengaturan!$J$19,I11,0)) -> 3500000 | K11: =IF(OR(C11="",I11=""),"",IF(E11=Pengaturan!$J$20,I11,0)) -> 0 | L11: =IF(C11="","",MONTH(C11)) -> 2 | M11: Sekretaris | O11: Seminar Nasional Pendidikan
B12: =IF(C12="","",ROW()-5) -> 7 | C12: 46068 | D12: KM-003 | E12: Pemasukan | F12: Sponsor | G12: Bank | H12: Sponsor seminar dari CV Maju Jaya | I12: 5000000 | J12: =IF(OR(C12="",I12=""),"",IF(E12=Pengaturan!$J$19,I12,0)) -> 5000000 | K12: =IF(OR(C12="",I12=""),"",IF(E12=Pengaturan!$J$20,I12,0)) -> 0 | L12: =IF(C12="","",MONTH(C12)) -> 2 | M12: Sekretaris | O12: Seminar Nasional Pendidikan
B13: =IF(C13="","",ROW()-5) -> 8 | C13: 46073 | D13: KK-005 | E13: Pengeluaran | F13: Kegiatan / Program | G13: Bank | H13: Penyelenggaraan seminar | I13: 6500000 | J13: =IF(OR(C13="",I13=""),"",IF(E13=Pengaturan!$J$19,I13,0)) -> 0 | K13: =IF(OR(C13="",I13=""),"",IF(E13=Pengaturan!$J$20,I13,0)) -> 6500000 | L13: =IF(C13="","",MONTH(C13)) -> 2 | M13: Ketua Panitia | N13: Dibiayai sponsor & kas | O13: Seminar Nasional Pendidikan
B14: =IF(C14="","",ROW()-5) -> 9 | C14: 46081 | D14: KK-006 | E14: Pengeluaran | F14: Administrasi Bank | G14: Bank | H14: Biaya administrasi bank Februari | I14: 15000 | J14: =IF(OR(C14="",I14=""),"",IF(E14=Pengaturan!$J$19,I14,0)) -> 0 | K14: =IF(OR(C14="",I14=""),"",IF(E14=Pengaturan!$J$20,I14,0)) -> 15000 | L14: =IF(C14="","",MONTH(C14)) -> 2 | M14: Bendahara | N14: Potongan otomatis
B15: =IF(C15="","",ROW()-5) -> 10 | C15: 46095 | D15: KM-004 | E15: Pemasukan | F15: Hasil Usaha / Bazar | G15: Kas Tunai | H15: Hasil bazar kuliner Ramadan | I15: 3200000 | J15: =IF(OR(C15="",I15=""),"",IF(E15=Pengaturan!$J$19,I15,0)) -> 3200000 | K15: =IF(OR(C15="",I15=""),"",IF(E15=Pengaturan!$J$20,I15,0)) -> 0 | L15: =IF(C15="","",MONTH(C15)) -> 3 | M15: Seksi Usaha | O15: Bazar & Buka Puasa Bersama
B16: =IF(C16="","",ROW()-5) -> 11 | C16: 46096 | D16: KK-007 | E16: Pengeluaran | F16: Konsumsi | G16: Kas Tunai | H16: Buka puasa bersama anggota | I16: 1200000 | J16: =IF(OR(C16="",I16=""),"",IF(E16=Pengaturan!$J$19,I16,0)) -> 0 | K16: =IF(OR(C16="",I16=""),"",IF(E16=Pengaturan!$J$20,I16,0)) -> 1200000 | L16: =IF(C16="","",MONTH(C16)) -> 3 | M16: Seksi Konsumsi | O16: Bazar & Buka Puasa Bersama
B17: =IF(C17="","",ROW()-5) -> 12 | C17: 46109 | D17: KK-008 | E17: Pengeluaran | F17: Administrasi Bank | G17: Bank | H17: Biaya administrasi bank Maret | I17: 15000 | J17: =IF(OR(C17="",I17=""),"",IF(E17=Pengaturan!$J$19,I17,0)) -> 0 | K17: =IF(OR(C17="",I17=""),"",IF(E17=Pengaturan!$J$20,I17,0)) -> 15000 | L17: =IF(C17="","",MONTH(C17)) -> 3 | M17: Bendahara | N17: Potongan otomatis
B18: =IF(C18="","",ROW()-5) -> 13 | C18: 46112 | D18: KM-005 | E18: Pemasukan | F18: Bunga Bank | G18: Bank | H18: Bunga tabungan triwulan I | I18: 45000 | J18: =IF(OR(C18="",I18=""),"",IF(E18=Pengaturan!$J$19,I18,0)) -> 45000 | K18: =IF(OR(C18="",I18=""),"",IF(E18=Pengaturan!$J$20,I18,0)) -> 0 | L18: =IF(C18="","",MONTH(C18)) -> 3 | M18: Bendahara
B19: =IF(C19="","",ROW()-5) -> 14 | C19: 46117 | D19: KK-009 | E19: Pengeluaran | F19: Sewa & Utilitas | G19: Bank | H19: Sewa sekretariat triwulan II | I19: 1500000 | J19: =IF(OR(C19="",I19=""),"",IF(E19=Pengaturan!$J$19,I19,0)) -> 0 | K19: =IF(OR(C19="",I19=""),"",IF(E19=Pengaturan!$J$20,I19,0)) -> 1500000 | L19: =IF(C19="","",MONTH(C19)) -> 4 | M19: Bendahara
B20: =IF(C20="","",ROW()-5) -> 15 | C20: 46134 | D20: KK-010 | E20: Pengeluaran | F20: Sosial / Santunan | G20: Kas Tunai | H20: Santunan anak yatim | I20: 2000000 | J20: =IF(OR(C20="",I20=""),"",IF(E20=Pengaturan!$J$19,I20,0)) -> 0 | K20: =IF(OR(C20="",I20=""),"",IF(E20=Pengaturan!$J$20,I20,0)) -> 2000000 | L20: =IF(C20="","",MONTH(C20)) -> 4 | M20: Seksi Sosial | O20: Santunan Anak Yatim
B21: =IF(C21="","",ROW()-5) -> 16 | C21: 46140 | D21: KK-011 | E21: Pengeluaran | F21: Administrasi Bank | G21: Bank | H21: Biaya administrasi bank April | I21: 15000 | J21: =IF(OR(C21="",I21=""),"",IF(E21=Pengaturan!$J$19,I21,0)) -> 0 | K21: =IF(OR(C21="",I21=""),"",IF(E21=Pengaturan!$J$20,I21,0)) -> 15000 | L21: =IF(C21="","",MONTH(C21)) -> 4 | M21: Bendahara | N21: Potongan otomatis
B22: =IF(C22="","",ROW()-5) -> 17 | C22: 46152 | D22: KK-012 | E22: Pengeluaran | F22: Transportasi | G22: Kas Tunai | H22: Transport koordinasi pengurus | I22: 350000 | J22: =IF(OR(C22="",I22=""),"",IF(E22=Pengaturan!$J$19,I22,0)) -> 0 | K22: =IF(OR(C22="",I22=""),"",IF(E22=Pengaturan!$J$20,I22,0)) -> 350000 | L22: =IF(C22="","",MONTH(C22)) -> 5 | M22: Sekretaris
B23: =IF(C23="","",ROW()-5) -> 18 | C23: 46170 | D23: KK-013 | E23: Pengeluaran | F23: Administrasi Bank | G23: Bank | H23: Biaya administrasi bank Mei | I23: 15000 | J23: =IF(OR(C23="",I23=""),"",IF(E23=Pengaturan!$J$19,I23,0)) -> 0 | K23: =IF(OR(C23="",I23=""),"",IF(E23=Pengaturan!$J$20,I23,0)) -> 15000 | L23: =IF(C23="","",MONTH(C23)) -> 5 | M23: Bendahara | N23: Potongan otomatis
B24: =IF(C24="","",ROW()-5) -> 19 | C24: 46181 | D24: KK-014 | E24: Pengeluaran | F24: Perlengkapan / Aset | G24: Bank | H24: Pembelian proyektor | I24: 4500000 | J24: =IF(OR(C24="",I24=""),"",IF(E24=Pengaturan!$J$19,I24,0)) -> 0 | K24: =IF(OR(C24="",I24=""),"",IF(E24=Pengaturan!$J$20,I24,0)) -> 4500000 | L24: =IF(C24="","",MONTH(C24)) -> 6 | M24: Bendahara | N24: Tercatat di sheet Aset
B25: =IF(C25="","",ROW()-5) -> 20 | C25: 46183 | D25: KM-006 | E25: Pemasukan | F25: Hibah / Bantuan | G25: Bank | H25: Bantuan dana kegiatan organisasi | I25: 4000000 | J25: =IF(OR(C25="",I25=""),"",IF(E25=Pengaturan!$J$19,I25,0)) -> 4000000 | K25: =IF(OR(C25="",I25=""),"",IF(E25=Pengaturan!$J$20,I25,0)) -> 0 | L25: =IF(C25="","",MONTH(C25)) -> 6 | M25: Ketua | O25: Pelatihan Peningkatan Kapasitas
B26: =IF(C26="","",ROW()-5) -> 21 | C26: 46193 | D26: KM-007 | E26: Pemasukan | F26: Pendaftaran / Tiket Event | G26: Bank | H26: Pendaftaran peserta pelatihan | I26: 1500000 | J26: =IF(OR(C26="",I26=""),"",IF(E26=Pengaturan!$J$19,I26,0)) -> 1500000 | K26: =IF(OR(C26="",I26=""),"",IF(E26=Pengaturan!$J$20,I26,0)) -> 0 | L26: =IF(C26="","",MONTH(C26)) -> 6 | M26: Sekretaris | O26: Pelatihan Peningkatan Kapasitas
B27: =IF(C27="","",ROW()-5) -> 22 | C27: 46193 | D27: KK-015 | E27: Pengeluaran | F27: Kegiatan / Program | G27: Bank | H27: Pelatihan peningkatan kapasitas anggota | I27: 2800000 | J27: =IF(OR(C27="",I27=""),"",IF(E27=Pengaturan!$J$19,I27,0)) -> 0 | K27: =IF(OR(C27="",I27=""),"",IF(E27=Pengaturan!$J$20,I27,0)) -> 2800000 | L27: =IF(C27="","",MONTH(C27)) -> 6 | M27: Ketua Panitia | O27: Pelatihan Peningkatan Kapasitas
B28: =IF(C28="","",ROW()-5) -> 23 | C28: 46194 | D28: KK-016 | E28: Pengeluaran | F28: Honor / Insentif | G28: Kas Tunai | H28: Honor narasumber pelatihan | I28: 1000000 | J28: =IF(OR(C28="",I28=""),"",IF(E28=Pengaturan!$J$19,I28,0)) -> 0 | K28: =IF(OR(C28="",I28=""),"",IF(E28=Pengaturan!$J$20,I28,0)) -> 1000000 | L28: =IF(C28="","",MONTH(C28)) -> 6 | M28: Bendahara | O28: Pelatihan Peningkatan Kapasitas
B29: =IF(C29="","",ROW()-5) -> 24 | C29: 46201 | D29: KK-017 | E29: Pengeluaran | F29: Administrasi Bank | G29: Bank | H29: Biaya administrasi bank Juni | I29: 15000 | J29: =IF(OR(C29="",I29=""),"",IF(E29=Pengaturan!$J$19,I29,0)) -> 0 | K29: =IF(OR(C29="",I29=""),"",IF(E29=Pengaturan!$J$20,I29,0)) -> 15000 | L29: =IF(C29="","",MONTH(C29)) -> 6 | M29: Bendahara | N29: Potongan otomatis
B30: =IF(C30="","",ROW()-5) -> 25 | C30: 46203 | D30: KM-008 | E30: Pemasukan | F30: Bunga Bank | G30: Bank | H30: Bunga tabungan triwulan II | I30: 48000 | J30: =IF(OR(C30="",I30=""),"",IF(E30=Pengaturan!$J$19,I30,0)) -> 48000 | K30: =IF(OR(C30="",I30=""),"",IF(E30=Pengaturan!$J$20,I30,0)) -> 0 | L30: =IF(C30="","",MONTH(C30)) -> 6 | M30: Bendahara
B31: =IF(C31="","",ROW()-5) -> 26 | C31: 46208 | D31: KK-018 | E31: Pengeluaran | F31: Sewa & Utilitas | G31: Bank | H31: Sewa sekretariat triwulan III | I31: 1500000 | J31: =IF(OR(C31="",I31=""),"",IF(E31=Pengaturan!$J$19,I31,0)) -> 0 | K31: =IF(OR(C31="",I31=""),"",IF(E31=Pengaturan!$J$20,I31,0)) -> 1500000 | L31: =IF(C31="","",MONTH(C31)) -> 7 | M31: Bendahara
B32: =IF(C32="","",ROW()-5) -> 27 | C32: 46231 | D32: KK-019 | E32: Pengeluaran | F32: Administrasi Bank | G32: Bank | H32: Biaya administrasi bank Juli | I32: 15000 | J32: =IF(OR(C32="",I32=""),"",IF(E32=Pengaturan!$J$19,I32,0)) -> 0 | K32: =IF(OR(C32="",I32=""),"",IF(E32=Pengaturan!$J$20,I32,0)) -> 15000 | L32: =IF(C32="","",MONTH(C32)) -> 7 | M32: Bendahara | N32: Potongan otomatis
B33: =IF(C33="","",ROW()-5) -> 28 | C33: 46251 | D33: KM-009 | E33: Pemasukan | F33: Donasi | G33: Kas Tunai | H33: Donasi anggota untuk HUT RI | I33: 1500000 | J33: =IF(OR(C33="",I33=""),"",IF(E33=Pengaturan!$J$19,I33,0)) -> 1500000 | K33: =IF(OR(C33="",I33=""),"",IF(E33=Pengaturan!$J$20,I33,0)) -> 0 | L33: =IF(C33="","",MONTH(C33)) -> 8 | M33: Seksi Acara | O33: Perayaan HUT RI
B34: =IF(C34="","",ROW()-5) -> 29 | C34: 46251 | D34: KK-020 | E34: Pengeluaran | F34: Kegiatan / Program | G34: Kas Tunai | H34: Lomba perayaan HUT RI | I34: 1300000 | J34: =IF(OR(C34="",I34=""),"",IF(E34=Pengaturan!$J$19,I34,0)) -> 0 | K34: =IF(OR(C34="",I34=""),"",IF(E34=Pengaturan!$J$20,I34,0)) -> 1300000 | L34: =IF(C34="","",MONTH(C34)) -> 8 | M34: Seksi Acara | O34: Perayaan HUT RI
B35: =IF(C35="","",ROW()-5) -> 30 | C35: 46262 | D35: KK-021 | E35: Pengeluaran | F35: Administrasi Bank | G35: Bank | H35: Biaya administrasi bank Agustus | I35: 15000 | J35: =IF(OR(C35="",I35=""),"",IF(E35=Pengaturan!$J$19,I35,0)) -> 0 | K35: =IF(OR(C35="",I35=""),"",IF(E35=Pengaturan!$J$20,I35,0)) -> 15000 | L35: =IF(C35="","",MONTH(C35)) -> 8 | M35: Bendahara | N35: Potongan otomatis
B36: =IF(C36="","",ROW()-5) -> 31 | C36: 46270 | D36: KK-022 | E36: Pengeluaran | F36: Perlengkapan / Aset | G36: Kas Tunai | H36: Pembelian kursi plastik dan banner | I36: 1750000 | J36: =IF(OR(C36="",I36=""),"",IF(E36=Pengaturan!$J$19,I36,0)) -> 0 | K36: =IF(OR(C36="",I36=""),"",IF(E36=Pengaturan!$J$20,I36,0)) -> 1750000 | L36: =IF(C36="","",MONTH(C36)) -> 9 | M36: Bendahara | N36: Tercatat di sheet Aset
B37: =IF(C37="","",ROW()-5) -> 32 | C37: 46283 | D37: KK-023 | E37: Pengeluaran | F37: Sosial / Santunan | G37: Kas Tunai | H37: Santunan musibah anggota | I37: 1000000 | J37: =IF(OR(C37="",I37=""),"",IF(E37=Pengaturan!$J$19,I37,0)) -> 0 | K37: =IF(OR(C37="",I37=""),"",IF(E37=Pengaturan!$J$20,I37,0)) -> 1000000 | L37: =IF(C37="","",MONTH(C37)) -> 9 | M37: Seksi Sosial
B38: =IF(C38="","",ROW()-5) -> 33 | C38: 46293 | D38: KK-024 | E38: Pengeluaran | F38: Administrasi Bank | G38: Bank | H38: Biaya administrasi bank September | I38: 15000 | J38: =IF(OR(C38="",I38=""),"",IF(E38=Pengaturan!$J$19,I38,0)) -> 0 | K38: =IF(OR(C38="",I38=""),"",IF(E38=Pengaturan!$J$20,I38,0)) -> 15000 | L38: =IF(C38="","",MONTH(C38)) -> 9 | M38: Bendahara | N38: Potongan otomatis
B39: =IF(C39="","",ROW()-5) -> 34 | C39: 46295 | D39: KM-010 | E39: Pemasukan | F39: Bunga Bank | G39: Bank | H39: Bunga tabungan triwulan III | I39: 50000 | J39: =IF(OR(C39="",I39=""),"",IF(E39=Pengaturan!$J$19,I39,0)) -> 50000 | K39: =IF(OR(C39="",I39=""),"",IF(E39=Pengaturan!$J$20,I39,0)) -> 0 | L39: =IF(C39="","",MONTH(C39)) -> 9 | M39: Bendahara
B40: =IF(C40="","",ROW()-5) -> 35 | C40: 46300 | D40: KK-025 | E40: Pengeluaran | F40: Sewa & Utilitas | G40: Bank | H40: Sewa sekretariat triwulan IV | I40: 1500000 | J40: =IF(OR(C40="",I40=""),"",IF(E40=Pengaturan!$J$19,I40,0)) -> 0 | K40: =IF(OR(C40="",I40=""),"",IF(E40=Pengaturan!$J$20,I40,0)) -> 1500000 | L40: =IF(C40="","",MONTH(C40)) -> 10 | M40: Bendahara
B41: =IF(C41="","",ROW()-5) -> 36 | C41: 46305 | D41: KK-026 | E41: Pengeluaran | F41: ATK & Percetakan | G41: Kas Tunai | H41: Fotokopi dan materai | I41: 180000 | J41: =IF(OR(C41="",I41=""),"",IF(E41=Pengaturan!$J$19,I41,0)) -> 0 | K41: =IF(OR(C41="",I41=""),"",IF(E41=Pengaturan!$J$20,I41,0)) -> 180000 | L41: =IF(C41="","",MONTH(C41)) -> 10 | M41: Sekretaris
...

Sheet Buku Kas
B1: DATA KEUANGAN HAPIA JEMBER
B2: ="BUKU KAS — otomatis dari sheet Transaksi, saldo berjalan per akun • Tahun Buku "&Pengaturan!$C$6 -> BUKU KAS — otomatis dari sheet Transaksi, saldo berjalan per akun • Tahun Buku 2026
B4: Jangan diisi manual — seluruh kolom terhubung ke sheet Transaksi.
B5: Tanggal | C5: No. Bukti | D5: Uraian | E5: Akun | F5: Masuk (Rp) | G5: Keluar (Rp) | H5: Saldo Kas Tunai | I5: Saldo Bank | J5: Saldo Total
B6: SALDO AWAL | H6: =Pengaturan!$C$10 -> 10000000 | I6: =Pengaturan!$C$11 -> 20000000 | J6: =H6+I6 -> 30000000
B7: =IF(Transaksi!C6="","",Transaksi!C6) -> 46027 | C7: =IF(Transaksi!C6="","",Transaksi!D6) -> KK-001 | D7: =IF(Transaksi!C6="","",Transaksi!H6) -> Sewa sekretariat triwulan I | E7: =IF(Transaksi!C6="","",Transaksi!G6) -> Bank | F7: =IF(Transaksi!C6="","",Transaksi!J6) -> 0 | G7: =IF(Transaksi!C6="","",Transaksi!K6) -> 1500000 | H7: =IF($B7="","",Pengaturan!$C$10+SUMIFS(Transaksi!$J$6:$J6,Transaksi!$G$6:$G6,Pengaturan!$F$19)-SUMIFS(Transaksi!$K$6:$K6,Transaksi!$G$6:$G6,Pengaturan!$F$19)) -> 10000000 | I7: =IF($B7="","",Pengaturan!$C$11+SUMIFS(Transaksi!$J$6:$J6,Transaksi!$G$6:$G6,Pengaturan!$F$20)-SUMIFS(Transaksi!$K$6:$K6,Transaksi!$G$6:$G6,Pengaturan!$F$20)) -> 18500000 | J7: =IF($B7="","",H7+I7) -> 28500000
B8: =IF(Transaksi!C7="","",Transaksi!C7) -> 46032 | C8: =IF(Transaksi!C7="","",Transaksi!D7) -> KM-001 | D8: =IF(Transaksi!C7="","",Transaksi!H7) -> Donasi Bapak H. Santoso untuk seminar | E8: =IF(Transaksi!C7="","",Transaksi!G7) -> Bank | F8: =IF(Transaksi!C7="","",Transaksi!J7) -> 2000000 | G8: =IF(Transaksi!C7="","",Transaksi!K7) -> 0 | H8: =IF($B8="","",Pengaturan!$C$10+SUMIFS(Transaksi!$J$6:$J7,Transaksi!$G$6:$G7,Pengaturan!$F$19)-SUMIFS(Transaksi!$K$6:$K7,Transaksi!$G$6:$G7,Pengaturan!$F$19)) -> 10000000 | I8: =IF($B8="","",Pengaturan!$C$11+SUMIFS(Transaksi!$J$6:$J7,Transaksi!$G$6:$G7,Pengaturan!$F$20)-SUMIFS(Transaksi!$K$6:$K7,Transaksi!$G$6:$G7,Pengaturan!$F$20)) -> 20500000 | J8: =IF($B8="","",H8+I8) -> 30500000
B9: =IF(Transaksi!C8="","",Transaksi!C8) -> 46034 | C9: =IF(Transaksi!C8="","",Transaksi!D8) -> KK-002 | D9: =IF(Transaksi!C8="","",Transaksi!H8) -> Cetak kartu anggota | E9: =IF(Transaksi!C8="","",Transaksi!G8) -> Kas Tunai | F9: =IF(Transaksi!C8="","",Transaksi!J8) -> 0 | G9: =IF(Transaksi!C8="","",Transaksi!K8) -> 450000 | H9: =IF($B9="","",Pengaturan!$C$10+SUMIFS(Transaksi!$J$6:$J8,Transaksi!$G$6:$G8,Pengaturan!$F$19)-SUMIFS(Transaksi!$K$6:$K8,Transaksi!$G$6:$G8,Pengaturan!$F$19)) -> 9550000 | I9: =IF($B9="","",Pengaturan!$C$11+SUMIFS(Transaksi!$J$6:$J8,Transaksi!$G$6:$G8,Pengaturan!$F$20)-SUMIFS(Transaksi!$K$6:$K8,Transaksi!$G$6:$G8,Pengaturan!$F$20)) -> 20500000 | J9: =IF($B9="","",H9+I9) -> 30050000
B10: =IF(Transaksi!C9="","",Transaksi!C9) -> 46047 | C10: =IF(Transaksi!C9="","",Transaksi!D9) -> KK-003 | D10: =IF(Transaksi!C9="","",Transaksi!H9) -> Konsumsi rapat kerja awal tahun | E10: =IF(Transaksi!C9="","",Transaksi!G9) -> Kas Tunai | F10: =IF(Transaksi!C9="","",Transaksi!J9) -> 0 | G10: =IF(Transaksi!C9="","",Transaksi!K9) -> 600000 | H10: =IF($B10="","",Pengaturan!$C$10+SUMIFS(Transaksi!$J$6:$J9,Transaksi!$G$6:$G9,Pengaturan!$F$19)-SUMIFS(Transaksi!$K$6:$K9,Transaksi!$G$6:$G9,Pengaturan!$F$19)) -> 8950000 | I10: =IF($B10="","",Pengaturan!$C$11+SUMIFS(Transaksi!$J$6:$J9,Transaksi!$G$6:$G9,Pengaturan!$F$20)-SUMIFS(Transaksi!$K$6:$K9,Transaksi!$G$6:$G9,Pengaturan!$F$20)) -> 20500000 | J10: =IF($B10="","",H10+I10) -> 29450000
B11: =IF(Transaksi!C10="","",Transaksi!C10) -> 46050 | C11: =IF(Transaksi!C10="","",Transaksi!D10) -> KK-004 | D11: =IF(Transaksi!C10="","",Transaksi!H10) -> Biaya administrasi bank Januari | E11: =IF(Transaksi!C10="","",Transaksi!G10) -> Bank | F11: =IF(Transaksi!C10="","",Transaksi!J10) -> 0 | G11: =IF(Transaksi!C10="","",Transaksi!K10) -> 15000 | H11: =IF($B11="","",Pengaturan!$C$10+SUMIFS(Transaksi!$J$6:$J10,Transaksi!$G$6:$G10,Pengaturan!$F$19)-SUMIFS(Transaksi!$K$6:$K10,Transaksi!$G$6:$G10,Pengaturan!$F$19)) -> 8950000 | I11: =IF($B11="","",Pengaturan!$C$11+SUMIFS(Transaksi!$J$6:$J10,Transaksi!$G$6:$G10,Pengaturan!$F$20)-SUMIFS(Transaksi!$K$6:$K10,Transaksi!$G$6:$G10,Pengaturan!$F$20)) -> 20485000 | J11: =IF($B11="","",H11+I11) -> 29435000
B12: =IF(Transaksi!C11="","",Transaksi!C11) -> 46065 | C12: =IF(Transaksi!C11="","",Transaksi!D11) -> KM-002 | D12: =IF(Transaksi!C11="","",Transaksi!H11) -> Pendaftaran peserta seminar | E12: =IF(Transaksi!C11="","",Transaksi!G11) -> Bank | F12: =IF(Transaksi!C11="","",Transaksi!J11) -> 3500000 | G12: =IF(Transaksi!C11="","",Transaksi!K11) -> 0 | H12: =IF($B12="","",Pengaturan!$C$10+SUMIFS(Transaksi!$J$6:$J11,Transaksi!$G$6:$G11,Pengaturan!$F$19)-SUMIFS(Transaksi!$K$6:$K11,Transaksi!$G$6:$G11,Pengaturan!$F$19)) -> 8950000 | I12: =IF($B12="","",Pengaturan!$C$11+SUMIFS(Transaksi!$J$6:$J11,Transaksi!$G$6:$G11,Pengaturan!$F$20)-SUMIFS(Transaksi!$K$6:$K11,Transaksi!$G$6:$G11,Pengaturan!$F$20)) -> 23985000 | J12: =IF($B12="","",H12+I12) -> 32935000
B13: =IF(Transaksi!C12="","",Transaksi!C12) -> 46068 | C13: =IF(Transaksi!C12="","",Transaksi!D12) -> KM-003 | D13: =IF(Transaksi!C12="","",Transaksi!H12) -> Sponsor seminar dari CV Maju Jaya | E13: =IF(Transaksi!C12="","",Transaksi!G12) -> Bank | F13: =IF(Transaksi!C12="","",Transaksi!J12) -> 5000000 | G13: =IF(Transaksi!C12="","",Transaksi!K12) -> 0 | H13: =IF($B13="","",Pengaturan!$C$10+SUMIFS(Transaksi!$J$6:$J12,Transaksi!$G$6:$G12,Pengaturan!$F$19)-SUMIFS(Transaksi!$K$6:$K12,Transaksi!$G$6:$G12,Pengaturan!$F$19)) -> 8950000 | I13: =IF($B13="","",Pengaturan!$C$11+SUMIFS(Transaksi!$J$6:$J12,Transaksi!$G$6:$G12,Pengaturan!$F$20)-SUMIFS(Transaksi!$K$6:$K12,Transaksi!$G$6:$G12,Pengaturan!$F$20)) -> 28985000 | J13: =IF($B13="","",H13+I13) -> 37935000
B14: =IF(Transaksi!C13="","",Transaksi!C13) -> 46073 | C14: =IF(Transaksi!C13="","",Transaksi!D13) -> KK-005 | D14: =IF(Transaksi!C13="","",Transaksi!H13) -> Penyelenggaraan seminar | E14: =IF(Transaksi!C13="","",Transaksi!G13) -> Bank | F14: =IF(Transaksi!C13="","",Transaksi!J13) -> 0 | G14: =IF(Transaksi!C13="","",Transaksi!K13) -> 6500000 | H14: =IF($B14="","",Pengaturan!$C$10+SUMIFS(Transaksi!$J$6:$J13,Transaksi!$G$6:$G13,Pengaturan!$F$19)-SUMIFS(Transaksi!$K$6:$K13,Transaksi!$G$6:$G13,Pengaturan!$F$19)) -> 8950000 | I14: =IF($B14="","",Pengaturan!$C$11+SUMIFS(Transaksi!$J$6:$J13,Transaksi!$G$6:$G13,Pengaturan!$F$20)-SUMIFS(Transaksi!$K$6:$K13,Transaksi!$G$6:$G13,Pengaturan!$F$20)) -> 22485000 | J14: =IF($B14="","",H14+I14) -> 31435000
B15: =IF(Transaksi!C14="","",Transaksi!C14) -> 46081 | C15: =IF(Transaksi!C14="","",Transaksi!D14) -> KK-006 | D15: =IF(Transaksi!C14="","",Transaksi!H14) -> Biaya administrasi bank Februari | E15: =IF(Transaksi!C14="","",Transaksi!G14) -> Bank | F15: =IF(Transaksi!C14="","",Transaksi!J14) -> 0 | G15: =IF(Transaksi!C14="","",Transaksi!K14) -> 15000 | H15: =IF($B15="","",Pengaturan!$C$10+SUMIFS(Transaksi!$J$6:$J14,Transaksi!$G$6:$G14,Pengaturan!$F$19)-SUMIFS(Transaksi!$K$6:$K14,Transaksi!$G$6:$G14,Pengaturan!$F$19)) -> 8950000 | I15: =IF($B15="","",Pengaturan!$C$11+SUMIFS(Transaksi!$J$6:$J14,Transaksi!$G$6:$G14,Pengaturan!$F$20)-SUMIFS(Transaksi!$K$6:$K14,Transaksi!$G$6:$G14,Pengaturan!$F$20)) -> 22470000 | J15: =IF($B15="","",H15+I15) -> 31420000
B16: =IF(Transaksi!C15="","",Transaksi!C15) -> 46095 | C16: =IF(Transaksi!C15="","",Transaksi!D15) -> KM-004 | D16: =IF(Transaksi!C15="","",Transaksi!H15) -> Hasil bazar kuliner Ramadan | E16: =IF(Transaksi!C15="","",Transaksi!G15) -> Kas Tunai | F16: =IF(Transaksi!C15="","",Transaksi!J15) -> 3200000 | G16: =IF(Transaksi!C15="","",Transaksi!K15) -> 0 | H16: =IF($B16="","",Pengaturan!$C$10+SUMIFS(Transaksi!$J$6:$J15,Transaksi!$G$6:$G15,Pengaturan!$F$19)-SUMIFS(Transaksi!$K$6:$K15,Transaksi!$G$6:$G15,Pengaturan!$F$19)) -> 12150000 | I16: =IF($B16="","",Pengaturan!$C$11+SUMIFS(Transaksi!$J$6:$J15,Transaksi!$G$6:$G15,Pengaturan!$F$20)-SUMIFS(Transaksi!$K$6:$K15,Transaksi!$G$6:$G15,Pengaturan!$F$20)) -> 22470000 | J16: =IF($B16="","",H16+I16) -> 34620000
B17: =IF(Transaksi!C16="","",Transaksi!C16) -> 46096 | C17: =IF(Transaksi!C16="","",Transaksi!D16) -> KK-007 | D17: =IF(Transaksi!C16="","",Transaksi!H16) -> Buka puasa bersama anggota | E17: =IF(Transaksi!C16="","",Transaksi!G16) -> Kas Tunai | F17: =IF(Transaksi!C16="","",Transaksi!J16) -> 0 | G17: =IF(Transaksi!C16="","",Transaksi!K16) -> 1200000 | H17: =IF($B17="","",Pengaturan!$C$10+SUMIFS(Transaksi!$J$6:$J16,Transaksi!$G$6:$G16,Pengaturan!$F$19)-SUMIFS(Transaksi!$K$6:$K16,Transaksi!$G$6:$G16,Pengaturan!$F$19)) -> 10950000 | I17: =IF($B17="","",Pengaturan!$C$11+SUMIFS(Transaksi!$J$6:$J16,Transaksi!$G$6:$G16,Pengaturan!$F$20)-SUMIFS(Transaksi!$K$6:$K16,Transaksi!$G$6:$G16,Pengaturan!$F$20)) -> 22470000 | J17: =IF($B17="","",H17+I17) -> 33420000
B18: =IF(Transaksi!C17="","",Transaksi!C17) -> 46109 | C18: =IF(Transaksi!C17="","",Transaksi!D17) -> KK-008 | D18: =IF(Transaksi!C17="","",Transaksi!H17) -> Biaya administrasi bank Maret | E18: =IF(Transaksi!C17="","",Transaksi!G17) -> Bank | F18: =IF(Transaksi!C17="","",Transaksi!J17) -> 0 | G18: =IF(Transaksi!C17="","",Transaksi!K17) -> 15000 | H18: =IF($B18="","",Pengaturan!$C$10+SUMIFS(Transaksi!$J$6:$J17,Transaksi!$G$6:$G17,Pengaturan!$F$19)-SUMIFS(Transaksi!$K$6:$K17,Transaksi!$G$6:$G17,Pengaturan!$F$19)) -> 10950000 | I18: =IF($B18="","",Pengaturan!$C$11+SUMIFS(Transaksi!$J$6:$J17,Transaksi!$G$6:$G17,Pengaturan!$F$20)-SUMIFS(Transaksi!$K$6:$K17,Transaksi!$G$6:$G17,Pengaturan!$F$20)) -> 22455000 | J18: =IF($B18="","",H18+I18) -> 33405000
... B506: =IF(Transaksi!C505="","",Transaksi!C505) | C506: =IF(Transaksi!C505="","",Transaksi!D505) | D506: =IF(Transaksi!C505="","",Transaksi!H505) | E506: =IF(Transaksi!C505="","",Transaksi!G505) | F506: =IF(Transaksi!C505="","",Transaksi!J505) | G506: =IF(Transaksi!C505="","",Transaksi!K505) | H506: =IF($B506="","",Pengaturan!$C$10+SUMIFS(Transaksi!$J$6:$J505,Transaksi!$G$6:$G505,Pengaturan!$F$19)-SUMIFS(Transaksi!$K$6:$K505,Transaksi!$G$6:$G505,Pengaturan!$F$19)) | I506: =IF($B506="","",Pengaturan!$C$11+SUMIFS(Transaksi!$J$6:$J505,Transaksi!$G$6:$G505,Pengaturan!$F$20)-SUMIFS(Transaksi!$K$6:$K505,Transaksi!$G$6:$G505,Pengaturan!$F$20)) | J506: =IF($B506="","",H506+I506)

Sheet Rekap Bulanan
B1: DATA KEUANGAN HAPIA JEMBER
B2: ="REKAP BULANAN — pemasukan, pengeluaran & saldo per bulan • Tahun Buku "&Pengaturan!$C$6 -> REKAP BULANAN — pemasukan, pengeluaran & saldo per bulan • Tahun Buku 2026
B5: No | C5: Bulan | D5: Saldo Awal (Rp) | E5: Pemasukan (Rp) | F5: Pengeluaran (Rp) | G5: Surplus / (Defisit) | H5: Saldo Akhir (Rp) | I5: Rasio Keluar
B6: 1 | C6: =INDEX(Pengaturan!$H$19:$H$30,B6) -> Januari | D6: =Pengaturan!$C$10+Pengaturan!$C$11 -> 30000000 | E6: =SUMIFS(Transaksi!$J$6:$J$505,Transaksi!$L$6:$L$505,B6) -> 2000000 | F6: =SUMIFS(Transaksi!$K$6:$K$505,Transaksi!$L$6:$L$505,B6) -> 2565000 | G6: =E6-F6 -> -565000 | H6: =D6+G6 -> 29435000 | I6: =IF(E6=0,0,F6/E6) -> 1.2825
B7: 2 | C7: =INDEX(Pengaturan!$H$19:$H$30,B7) -> Februari | D7: =H6 -> 29435000 | E7: =SUMIFS(Transaksi!$J$6:$J$505,Transaksi!$L$6:$L$505,B7) -> 8500000 | F7: =SUMIFS(Transaksi!$K$6:$K$505,Transaksi!$L$6:$L$505,B7) -> 6515000 | G7: =E7-F7 -> 1985000 | H7: =D7+G7 -> 31420000 | I7: =IF(E7=0,0,F7/E7) -> 0.76647059
B8: 3 | C8: =INDEX(Pengaturan!$H$19:$H$30,B8) -> Maret | D8: =H7 -> 31420000 | E8: =SUMIFS(Transaksi!$J$6:$J$505,Transaksi!$L$6:$L$505,B8) -> 3245000 | F8: =SUMIFS(Transaksi!$K$6:$K$505,Transaksi!$L$6:$L$505,B8) -> 1215000 | G8: =E8-F8 -> 2030000 | H8: =D8+G8 -> 33450000 | I8: =IF(E8=0,0,F8/E8) -> 0.37442219
B9: 4 | C9: =INDEX(Pengaturan!$H$19:$H$30,B9) -> April | D9: =H8 -> 33450000 | E9: =SUMIFS(Transaksi!$J$6:$J$505,Transaksi!$L$6:$L$505,B9) -> 0 | F9: =SUMIFS(Transaksi!$K$6:$K$505,Transaksi!$L$6:$L$505,B9) -> 3515000 | G9: =E9-F9 -> -3515000 | H9: =D9+G9 -> 29935000 | I9: =IF(E9=0,0,F9/E9) -> 0
B10: 5 | C10: =INDEX(Pengaturan!$H$19:$H$30,B10) -> Mei | D10: =H9 -> 29935000 | E10: =SUMIFS(Transaksi!$J$6:$J$505,Transaksi!$L$6:$L$505,B10) -> 0 | F10: =SUMIFS(Transaksi!$K$6:$K$505,Transaksi!$L$6:$L$505,B10) -> 365000 | G10: =E10-F10 -> -365000 | H10: =D10+G10 -> 29570000 | I10: =IF(E10=0,0,F10/E10) -> 0
B11: 6 | C11: =INDEX(Pengaturan!$H$19:$H$30,B11) -> Juni | D11: =H10 -> 29570000 | E11: =SUMIFS(Transaksi!$J$6:$J$505,Transaksi!$L$6:$L$505,B11) -> 5548000 | F11: =SUMIFS(Transaksi!$K$6:$K$505,Transaksi!$L$6:$L$505,B11) -> 8315000 | G11: =E11-F11 -> -2767000 | H11: =D11+G11 -> 26803000 | I11: =IF(E11=0,0,F11/E11) -> 1.4987383
B12: 7 | C12: =INDEX(Pengaturan!$H$19:$H$30,B12) -> Juli | D12: =H11 -> 26803000 | E12: =SUMIFS(Transaksi!$J$6:$J$505,Transaksi!$L$6:$L$505,B12) -> 0 | F12: =SUMIFS(Transaksi!$K$6:$K$505,Transaksi!$L$6:$L$505,B12) -> 1515000 | G12: =E12-F12 -> -1515000 | H12: =D12+G12 -> 25288000 | I12: =IF(E12=0,0,F12/E12) -> 0
B13: 8 | C13: =INDEX(Pengaturan!$H$19:$H$30,B13) -> Agustus | D13: =H12 -> 25288000 | E13: =SUMIFS(Transaksi!$J$6:$J$505,Transaksi!$L$6:$L$505,B13) -> 1500000 | F13: =SUMIFS(Transaksi!$K$6:$K$505,Transaksi!$L$6:$L$505,B13) -> 1315000 | G13: =E13-F13 -> 185000 | H13: =D13+G13 -> 25473000 | I13: =IF(E13=0,0,F13/E13) -> 0.87666667
B14: 9 | C14: =INDEX(Pengaturan!$H$19:$H$30,B14) -> September | D14: =H13 -> 25473000 | E14: =SUMIFS(Transaksi!$J$6:$J$505,Transaksi!$L$6:$L$505,B14) -> 50000 | F14: =SUMIFS(Transaksi!$K$6:$K$505,Transaksi!$L$6:$L$505,B14) -> 2765000 | G14: =E14-F14 -> -2715000 | H14: =D14+G14 -> 22758000 | I14: =IF(E14=0,0,F14/E14) -> 55.3
B15: 10 | C15: =INDEX(Pengaturan!$H$19:$H$30,B15) -> Oktober | D15: =H14 -> 22758000 | E15: =SUMIFS(Transaksi!$J$6:$J$505,Transaksi!$L$6:$L$505,B15) -> 0 | F15: =SUMIFS(Transaksi!$K$6:$K$505,Transaksi!$L$6:$L$505,B15) -> 2445000 | G15: =E15-F15 -> -2445000 | H15: =D15+G15 -> 20313000 | I15: =IF(E15=0,0,F15/E15) -> 0
B16: 11 | C16: =INDEX(Pengaturan!$H$19:$H$30,B16) -> November | D16: =H15 -> 20313000 | E16: =SUMIFS(Transaksi!$J$6:$J$505,Transaksi!$L$6:$L$505,B16) -> 0 | F16: =SUMIFS(Transaksi!$K$6:$K$505,Transaksi!$L$6:$L$505,B16) -> 0 | G16: =E16-F16 -> 0 | H16: =D16+G16 -> 20313000 | I16: =IF(E16=0,0,F16/E16) -> 0
B17: 12 | C17: =INDEX(Pengaturan!$H$19:$H$30,B17) -> Desember | D17: =H16 -> 20313000 | E17: =SUMIFS(Transaksi!$J$6:$J$505,Transaksi!$L$6:$L$505,B17) -> 0 | F17: =SUMIFS(Transaksi!$K$6:$K$505,Transaksi!$L$6:$L$505,B17) -> 0 | G17: =E17-F17 -> 0 | H17: =D17+G17 -> 20313000 | I17: =IF(E17=0,0,F17/E17) -> 0
B18: TOTAL | D18: =D6 -> 30000000 | E18: =SUM(E6:E17) -> 20843000 | F18: =SUM(F6:F17) -> 30530000 | G18: =SUM(G6:G17) -> -9687000 | H18: =D18+G18 -> 20313000 | I18: =IF(E18=0,0,F18/E18) -> 1.4647604
B20: Catatan: grafik di bawah dan di Dashboard otomatis mengikuti tabel ini.

Sheet Anggaran
B1: DATA KEUANGAN HAPIA JEMBER
B2: ="ANGGARAN vs REALISASI — target tahunan dibanding data Transaksi • Tahun Buku "&Pengaturan!$C$6 -> ANGGARAN vs REALISASI — target tahunan dibanding data Transaksi • Tahun Buku 2026
B4: A. PEMASUKAN (Target vs Realisasi)
B5: No | C5: Kategori | D5: Target Tahunan (Rp) | E5: Realisasi (Rp) | F5: Selisih (Rp) | G5: % Tercapai | H5: Status
B6: =IF(C6="","",1) -> 1 | C6: =IF(Pengaturan!$B$19="","",Pengaturan!$B$19) -> Donasi | D6: 4000000 | E6: =IF(C6="","",SUMIFS(Transaksi!$J$6:$J$505,Transaksi!$F$6:$F$505,C6)) -> 3500000 | F6: =IF(C6="","",E6-N(D6)) -> -500000 | G6: =IF(C6="","",IF(N(D6)=0,0,E6/D6)) -> 0.875 | H6: =IF(C6="","",IF(G6>=1,"Tercapai",IF(G6>=0.5,"Berjalan","Rendah"))) -> Berjalan
B7: =IF(C7="","",2) -> 2 | C7: =IF(Pengaturan!$B$20="","",Pengaturan!$B$20) -> Sponsor | D7: 8000000 | E7: =IF(C7="","",SUMIFS(Transaksi!$J$6:$J$505,Transaksi!$F$6:$F$505,C7)) -> 5000000 | F7: =IF(C7="","",E7-N(D7)) -> -3000000 | G7: =IF(C7="","",IF(N(D7)=0,0,E7/D7)) -> 0.625 | H7: =IF(C7="","",IF(G7>=1,"Tercapai",IF(G7>=0.5,"Berjalan","Rendah"))) -> Berjalan
B8: =IF(C8="","",3) -> 3 | C8: =IF(Pengaturan!$B$21="","",Pengaturan!$B$21) -> Pendaftaran / Tiket Event | D8: 7000000 | E8: =IF(C8="","",SUMIFS(Transaksi!$J$6:$J$505,Transaksi!$F$6:$F$505,C8)) -> 5000000 | F8: =IF(C8="","",E8-N(D8)) -> -2000000 | G8: =IF(C8="","",IF(N(D8)=0,0,E8/D8)) -> 0.71428571 | H8: =IF(C8="","",IF(G8>=1,"Tercapai",IF(G8>=0.5,"Berjalan","Rendah"))) -> Berjalan
B9: =IF(C9="","",4) -> 4 | C9: =IF(Pengaturan!$B$22="","",Pengaturan!$B$22) -> Hasil Usaha / Bazar | D9: 4000000 | E9: =IF(C9="","",SUMIFS(Transaksi!$J$6:$J$505,Transaksi!$F$6:$F$505,C9)) -> 3200000 | F9: =IF(C9="","",E9-N(D9)) -> -800000 | G9: =IF(C9="","",IF(N(D9)=0,0,E9/D9)) -> 0.8 | H9: =IF(C9="","",IF(G9>=1,"Tercapai",IF(G9>=0.5,"Berjalan","Rendah"))) -> Berjalan
B10: =IF(C10="","",5) -> 5 | C10: =IF(Pengaturan!$B$23="","",Pengaturan!$B$23) -> Hibah / Bantuan | D10: 4000000 | E10: =IF(C10="","",SUMIFS(Transaksi!$J$6:$J$505,Transaksi!$F$6:$F$505,C10)) -> 4000000 | F10: =IF(C10="","",E10-N(D10)) -> 0 | G10: =IF(C10="","",IF(N(D10)=0,0,E10/D10)) -> 1 | H10: =IF(C10="","",IF(G10>=1,"Tercapai",IF(G10>=0.5,"Berjalan","Rendah"))) -> Tercapai
B11: =IF(C11="","",6) -> 6 | C11: =IF(Pengaturan!$B$24="","",Pengaturan!$B$24) -> Bunga Bank | D11: 200000 | E11: =IF(C11="","",SUMIFS(Transaksi!$J$6:$J$505,Transaksi!$F$6:$F$505,C11)) -> 143000 | F11: =IF(C11="","",E11-N(D11)) -> -57000 | G11: =IF(C11="","",IF(N(D11)=0,0,E11/D11)) -> 0.715 | H11: =IF(C11="","",IF(G11>=1,"Tercapai",IF(G11>=0.5,"Berjalan","Rendah"))) -> Berjalan
B12: =IF(C12="","",7) -> 7 | C12: =IF(Pengaturan!$B$25="","",Pengaturan!$B$25) -> Pemasukan Lain-lain | D12: 500000 | E12: =IF(C12="","",SUMIFS(Transaksi!$J$6:$J$505,Transaksi!$F$6:$F$505,C12)) -> 0 | F12: =IF(C12="","",E12-N(D12)) -> -500000 | G12: =IF(C12="","",IF(N(D12)=0,0,E12/D12)) -> 0 | H12: =IF(C12="","",IF(G12>=1,"Tercapai",IF(G12>=0.5,"Berjalan","Rendah"))) -> Rendah
B13: =IF(C13="","",8) | C13: =IF(Pengaturan!$B$26="","",Pengaturan!$B$26) | E13: =IF(C13="","",SUMIFS(Transaksi!$J$6:$J$505,Transaksi!$F$6:$F$505,C13)) | F13: =IF(C13="","",E13-N(D13)) | G13: =IF(C13="","",IF(N(D13)=0,0,E13/D13)) | H13: =IF(C13="","",IF(G13>=1,"Tercapai",IF(G13>=0.5,"Berjalan","Rendah")))
B14: TOTAL PEMASUKAN | D14: =SUM(D6:D13) -> 27700000 | E14: =SUM(E6:E13) -> 20843000 | F14: =E14-D14 -> -6857000 | G14: =IF(D14=0,0,E14/D14) -> 0.75245487
B17: B. PENGELUARAN (Anggaran vs Realisasi)
B18: No | C18: Kategori | D18: Anggaran Tahunan (Rp) | E18: Realisasi (Rp) | F18: Sisa Anggaran (Rp) | G18: % Terserap | H18: Status
B19: =IF(C19="","",1) -> 1 | C19: =IF(Pengaturan!$D$19="","",Pengaturan!$D$19) -> Kegiatan / Program | D19: 15000000 | E19: =IF(C19="","",SUMIFS(Transaksi!$K$6:$K$505,Transaksi!$F$6:$F$505,C19)) -> 10600000 | F19: =IF(C19="","",N(D19)-E19) -> 4400000 | G19: =IF(C19="","",IF(N(D19)=0,IF(E19>0,1.01,0),E19/D19)) -> 0.70666667 | H19: =IF(C19="","",IF(G19>1,"Melebihi",IF(G19>=Pengaturan!$C$15,"Waspada","Aman"))) -> Aman
B20: =IF(C20="","",2) -> 2 | C20: =IF(Pengaturan!$D$20="","",Pengaturan!$D$20) -> Konsumsi | D20: 3000000 | E20: =IF(C20="","",SUMIFS(Transaksi!$K$6:$K$505,Transaksi!$F$6:$F$505,C20)) -> 2300000 | F20: =IF(C20="","",N(D20)-E20) -> 700000 | G20: =IF(C20="","",IF(N(D20)=0,IF(E20>0,1.01,0),E20/D20)) -> 0.76666667 | H20: =IF(C20="","",IF(G20>1,"Melebihi",IF(G20>=Pengaturan!$C$15,"Waspada","Aman"))) -> Aman
B21: =IF(C21="","",3) -> 3 | C21: =IF(Pengaturan!$D$21="","",Pengaturan!$D$21) -> Transportasi | D21: 1000000 | E21: =IF(C21="","",SUMIFS(Transaksi!$K$6:$K$505,Transaksi!$F$6:$F$505,C21)) -> 600000 | F21: =IF(C21="","",N(D21)-E21) -> 400000 | G21: =IF(C21="","",IF(N(D21)=0,IF(E21>0,1.01,0),E21/D21)) -> 0.6 | H21: =IF(C21="","",IF(G21>1,"Melebihi",IF(G21>=Pengaturan!$C$15,"Waspada","Aman"))) -> Aman
B22: =IF(C22="","",4) -> 4 | C22: =IF(Pengaturan!$D$22="","",Pengaturan!$D$22) -> ATK & Percetakan | D22: 700000 | E22: =IF(C22="","",SUMIFS(Transaksi!$K$6:$K$505,Transaksi!$F$6:$F$505,C22)) -> 630000 | F22: =IF(C22="","",N(D22)-E22) -> 70000 | G22: =IF(C22="","",IF(N(D22)=0,IF(E22>0,1.01,0),E22/D22)) -> 0.9 | H22: =IF(C22="","",IF(G22>1,"Melebihi",IF(G22>=Pengaturan!$C$15,"Waspada","Aman"))) -> Waspada
B23: =IF(C23="","",5) -> 5 | C23: =IF(Pengaturan!$D$23="","",Pengaturan!$D$23) -> Sewa & Utilitas | D23: 6000000 | E23: =IF(C23="","",SUMIFS(Transaksi!$K$6:$K$505,Transaksi!$F$6:$F$505,C23)) -> 6000000 | F23: =IF(C23="","",N(D23)-E23) -> 0 | G23: =IF(C23="","",IF(N(D23)=0,IF(E23>0,1.01,0),E23/D23)) -> 1 | H23: =IF(C23="","",IF(G23>1,"Melebihi",IF(G23>=Pengaturan!$C$15,"Waspada","Aman"))) -> Waspada
B24: =IF(C24="","",6) -> 6 | C24: =IF(Pengaturan!$D$24="","",Pengaturan!$D$24) -> Honor / Insentif | D24: 1500000 | E24: =IF(C24="","",SUMIFS(Transaksi!$K$6:$K$505,Transaksi!$F$6:$F$505,C24)) -> 1000000 | F24: =IF(C24="","",N(D24)-E24) -> 500000 | G24: =IF(C24="","",IF(N(D24)=0,IF(E24>0,1.01,0),E24/D24)) -> 0.66666667 | H24: =IF(C24="","",IF(G24>1,"Melebihi",IF(G24>=Pengaturan!$C$15,"Waspada","Aman"))) -> Aman
B25: =IF(C25="","",7) -> 7 | C25: =IF(Pengaturan!$D$25="","",Pengaturan!$D$25) -> Sosial / Santunan | D25: 2500000 | E25: =IF(C25="","",SUMIFS(Transaksi!$K$6:$K$505,Transaksi!$F$6:$F$505,C25)) -> 3000000 | F25: =IF(C25="","",N(D25)-E25) -> -500000 | G25: =IF(C25="","",IF(N(D25)=0,IF(E25>0,1.01,0),E25/D25)) -> 1.2 | H25: =IF(C25="","",IF(G25>1,"Melebihi",IF(G25>=Pengaturan!$C$15,"Waspada","Aman"))) -> Melebihi
B26: =IF(C26="","",8) -> 8 | C26: =IF(Pengaturan!$D$26="","",Pengaturan!$D$26) -> Perlengkapan / Aset | D26: 7000000 | E26: =IF(C26="","",SUMIFS(Transaksi!$K$6:$K$505,Transaksi!$F$6:$F$505,C26)) -> 6250000 | F26: =IF(C26="","",N(D26)-E26) -> 750000 | G26: =IF(C26="","",IF(N(D26)=0,IF(E26>0,1.01,0),E26/D26)) -> 0.89285714 | H26: =IF(C26="","",IF(G26>1,"Melebihi",IF(G26>=Pengaturan!$C$15,"Waspada","Aman"))) -> Waspada
B27: =IF(C27="","",9) -> 9 | C27: =IF(Pengaturan!$D$27="","",Pengaturan!$D$27) -> Administrasi Bank | D27: 200000 | E27: =IF(C27="","",SUMIFS(Transaksi!$K$6:$K$505,Transaksi!$F$6:$F$505,C27)) -> 150000 | F27: =IF(C27="","",N(D27)-E27) -> 50000 | G27: =IF(C27="","",IF(N(D27)=0,IF(E27>0,1.01,0),E27/D27)) -> 0.75 | H27: =IF(C27="","",IF(G27>1,"Melebihi",IF(G27>=Pengaturan!$C$15,"Waspada","Aman"))) -> Aman
B28: =IF(C28="","",10) -> 10 | C28: =IF(Pengaturan!$D$28="","",Pengaturan!$D$28) -> Pengeluaran Lain-lain | D28: 500000 | E28: =IF(C28="","",SUMIFS(Transaksi!$K$6:$K$505,Transaksi!$F$6:$F$505,C28)) -> 0 | F28: =IF(C28="","",N(D28)-E28) -> 500000 | G28: =IF(C28="","",IF(N(D28)=0,IF(E28>0,1.01,0),E28/D28)) -> 0 | H28: =IF(C28="","",IF(G28>1,"Melebihi",IF(G28>=Pengaturan!$C$15,"Waspada","Aman"))) -> Aman
B29: =IF(C29="","",11) | C29: =IF(Pengaturan!$D$29="","",Pengaturan!$D$29) | E29: =IF(C29="","",SUMIFS(Transaksi!$K$6:$K$505,Transaksi!$F$6:$F$505,C29)) | F29: =IF(C29="","",N(D29)-E29) | G29: =IF(C29="","",IF(N(D29)=0,IF(E29>0,1.01,0),E29/D29)) | H29: =IF(C29="","",IF(G29>1,"Melebihi",IF(G29>=Pengaturan!$C$15,"Waspada","Aman")))
B30: =IF(C30="","",12) | C30: =IF(Pengaturan!$D$30="","",Pengaturan!$D$30) | E30: =IF(C30="","",SUMIFS(Transaksi!$K$6:$K$505,Transaksi!$F$6:$F$505,C30)) | F30: =IF(C30="","",N(D30)-E30) | G30: =IF(C30="","",IF(N(D30)=0,IF(E30>0,1.01,0),E30/D30)) | H30: =IF(C30="","",IF(G30>1,"Melebihi",IF(G30>=Pengaturan!$C$15,"Waspada","Aman")))
B31: TOTAL PENGELUARAN | D31: =SUM(D19:D30) -> 37400000 | E31: =SUM(E19:E30) -> 30530000 | F31: =D31-E31 -> 6870000 | G31: =IF(D31=0,0,E31/D31) -> 0.81631016
B34: C. SURPLUS / (DEFISIT)
C35: Rencana (Target Pemasukan − Anggaran Pengeluaran) | D35: =D14-D31 -> -9700000
C36: Realisasi (Pemasukan − Pengeluaran) | D36: =E14-E31 -> -9687000
C38: Pengecekan: total realisasi di atas harus sama dengan total di sheet Transaksi.
C39: Selisih pemasukan vs Transaksi: | E39: =E14-SUM(Transaksi!$J$6:$J$505) -> 0 | F39: =IF(E39=0,"✔ Sesuai","⚠ Ada transaksi dengan kategori di luar daftar") -> ✔ Sesuai
C40: Selisih pengeluaran vs Transaksi: | E40: =E31-SUM(Transaksi!$K$6:$K$505) -> 0 | F40: =IF(E40=0,"✔ Sesuai","⚠ Ada transaksi dengan kategori di luar daftar") -> ✔ Sesuai

Sheet Event
B1: DATA KEUANGAN HAPIA JEMBER
B2: ="EVENT / KEGIATAN — total keuangan tiap event, otomatis dari kolom Event di sheet Transaksi • Tahun Buku "&Pengaturan!$C$6 -> EVENT / KEGIATAN — total keuangan tiap event, otomatis dari kolom Event di sheet Transaksi • Tahun Buku 2026
B4: JUMLAH EVENT | D4: TOTAL PEMASUKAN EVENT | G4: TOTAL PENGELUARAN EVENT | J4: HASIL BERSIH EVENT | M4: EVENT MELEBIHI ANGGARAN
B5: =COUNTA(C9:C28) -> 8 | D5: =I29 -> 20700000 | G5: =J29 -> 16150000 | J5: =K29 -> 4550000 | M5: =COUNTIF(O9:O28,"Melebihi") -> 1
B7: Cara pakai: (1) daftarkan event di tabel ini (kolom putih), (2) di sheet Transaksi pilih nama event pada kolom 'Event' untuk setiap transaksi terkait. Kolom krem terisi otomatis.
B8: No | C8: Nama Event | D8: Tgl Mulai | E8: Tgl Selesai | F8: Lokasi | G8: Penanggung Jawab | H8: Anggaran (Rp) | I8: Pemasukan (Rp) | J8: Pengeluaran (Rp) | K8: Hasil Bersih (Rp) | L8: Serapan Anggaran | M8: Jml Transaksi | N8: Status Waktu | O8: Status Anggaran
B9: =IF(C9="","",ROW()-8) -> 1 | C9: Rapat Kerja Awal Tahun | D9: 46047 | E9: 46047 | F9: Sekretariat HAPIA | G9: Sekretaris | H9: 1000000 | I9: =IF(C9="","",SUMIFS(Transaksi!$J$6:$J$505,Transaksi!$O$6:$O$505,C9)) -> 0 | J9: =IF(C9="","",SUMIFS(Transaksi!$K$6:$K$505,Transaksi!$O$6:$O$505,C9)) -> 600000 | K9: =IF(C9="","",I9-J9) -> -600000 | L9: =IF(C9="","",IF(N(H9)=0,IF(J9>0,1.01,0),J9/H9)) -> 0.6 | M9: =IF(C9="","",COUNTIF(Transaksi!$O$6:$O$505,C9)) -> 1 | N9: =IF(C9="","",IF(OR(D9="",E9=""),"-",IF(E9<Pengaturan!$C$14,"Selesai",IF(D9>Pengaturan!$C$14,"Direncanakan","Berjalan")))) -> Selesai | O9: =IF(C9="","",IF(L9>1,"Melebihi",IF(L9>=Pengaturan!$C$15,"Waspada","Aman"))) -> Aman
B10: =IF(C10="","",ROW()-8) -> 2 | C10: Seminar Nasional Pendidikan | D10: 46073 | E10: 46073 | F10: Aula Kampus Jember | G10: Ketua Panitia | H10: 8000000 | I10: =IF(C10="","",SUMIFS(Transaksi!$J$6:$J$505,Transaksi!$O$6:$O$505,C10)) -> 10500000 | J10: =IF(C10="","",SUMIFS(Transaksi!$K$6:$K$505,Transaksi!$O$6:$O$505,C10)) -> 6500000 | K10: =IF(C10="","",I10-J10) -> 4000000 | L10: =IF(C10="","",IF(N(H10)=0,IF(J10>0,1.01,0),J10/H10)) -> 0.8125 | M10: =IF(C10="","",COUNTIF(Transaksi!$O$6:$O$505,C10)) -> 4 | N10: =IF(C10="","",IF(OR(D10="",E10=""),"-",IF(E10<Pengaturan!$C$14,"Selesai",IF(D10>Pengaturan!$C$14,"Direncanakan","Berjalan")))) -> Selesai | O10: =IF(C10="","",IF(L10>1,"Melebihi",IF(L10>=Pengaturan!$C$15,"Waspada","Aman"))) -> Waspada
B11: =IF(C11="","",ROW()-8) -> 3 | C11: Bazar & Buka Puasa Bersama | D11: 46095 | E11: 46096 | F11: Halaman Sekretariat | G11: Seksi Usaha | H11: 2500000 | I11: =IF(C11="","",SUMIFS(Transaksi!$J$6:$J$505,Transaksi!$O$6:$O$505,C11)) -> 3200000 | J11: =IF(C11="","",SUMIFS(Transaksi!$K$6:$K$505,Transaksi!$O$6:$O$505,C11)) -> 1200000 | K11: =IF(C11="","",I11-J11) -> 2000000 | L11: =IF(C11="","",IF(N(H11)=0,IF(J11>0,1.01,0),J11/H11)) -> 0.48 | M11: =IF(C11="","",COUNTIF(Transaksi!$O$6:$O$505,C11)) -> 2 | N11: =IF(C11="","",IF(OR(D11="",E11=""),"-",IF(E11<Pengaturan!$C$14,"Selesai",IF(D11>Pengaturan!$C$14,"Direncanakan","Berjalan")))) -> Selesai | O11: =IF(C11="","",IF(L11>1,"Melebihi",IF(L11>=Pengaturan!$C$15,"Waspada","Aman"))) -> Aman
B12: =IF(C12="","",ROW()-8) -> 4 | C12: Santunan Anak Yatim | D12: 46134 | E12: 46134 | F12: Panti Asuhan Jember | G12: Seksi Sosial | H12: 2500000 | I12: =IF(C12="","",SUMIFS(Transaksi!$J$6:$J$505,Transaksi!$O$6:$O$505,C12)) -> 0 | J12: =IF(C12="","",SUMIFS(Transaksi!$K$6:$K$505,Transaksi!$O$6:$O$505,C12)) -> 2000000 | K12: =IF(C12="","",I12-J12) -> -2000000 | L12: =IF(C12="","",IF(N(H12)=0,IF(J12>0,1.01,0),J12/H12)) -> 0.8 | M12: =IF(C12="","",COUNTIF(Transaksi!$O$6:$O$505,C12)) -> 1 | N12: =IF(C12="","",IF(OR(D12="",E12=""),"-",IF(E12<Pengaturan!$C$14,"Selesai",IF(D12>Pengaturan!$C$14,"Direncanakan","Berjalan")))) -> Selesai | O12: =IF(C12="","",IF(L12>1,"Melebihi",IF(L12>=Pengaturan!$C$15,"Waspada","Aman"))) -> Waspada
B13: =IF(C13="","",ROW()-8) -> 5 | C13: Pelatihan Peningkatan Kapasitas | D13: 46193 | E13: 46194 | F13: Gedung Serbaguna | G13: Ketua Panitia | H13: 4500000 | I13: =IF(C13="","",SUMIFS(Transaksi!$J$6:$J$505,Transaksi!$O$6:$O$505,C13)) -> 5500000 | J13: =IF(C13="","",SUMIFS(Transaksi!$K$6:$K$505,Transaksi!$O$6:$O$505,C13)) -> 3800000 | K13: =IF(C13="","",I13-J13) -> 1700000 | L13: =IF(C13="","",IF(N(H13)=0,IF(J13>0,1.01,0),J13/H13)) -> 0.84444444 | M13: =IF(C13="","",COUNTIF(Transaksi!$O$6:$O$505,C13)) -> 4 | N13: =IF(C13="","",IF(OR(D13="",E13=""),"-",IF(E13<Pengaturan!$C$14,"Selesai",IF(D13>Pengaturan!$C$14,"Direncanakan","Berjalan")))) -> Selesai | O13: =IF(C13="","",IF(L13>1,"Melebihi",IF(L13>=Pengaturan!$C$15,"Waspada","Aman"))) -> Waspada
B14: =IF(C14="","",ROW()-8) -> 6 | C14: Perayaan HUT RI | D14: 46251 | E14: 46251 | F14: Lapangan Sekretariat | G14: Seksi Acara | H14: 1200000 | I14: =IF(C14="","",SUMIFS(Transaksi!$J$6:$J$505,Transaksi!$O$6:$O$505,C14)) -> 1500000 | J14: =IF(C14="","",SUMIFS(Transaksi!$K$6:$K$505,Transaksi!$O$6:$O$505,C14)) -> 1300000 | K14: =IF(C14="","",I14-J14) -> 200000 | L14: =IF(C14="","",IF(N(H14)=0,IF(J14>0,1.01,0),J14/H14)) -> 1.0833333 | M14: =IF(C14="","",COUNTIF(Transaksi!$O$6:$O$505,C14)) -> 2 | N14: =IF(C14="","",IF(OR(D14="",E14=""),"-",IF(E14<Pengaturan!$C$14,"Selesai",IF(D14>Pengaturan!$C$14,"Direncanakan","Berjalan")))) -> Selesai | O14: =IF(C14="","",IF(L14>1,"Melebihi",IF(L14>=Pengaturan!$C$15,"Waspada","Aman"))) -> Melebihi
B15: =IF(C15="","",ROW()-8) -> 7 | C15: Rapat Evaluasi Triwulan III | D15: 46307 | E15: 46307 | F15: Sekretariat HAPIA | G15: Sekretaris | H15: 600000 | I15: =IF(C15="","",SUMIFS(Transaksi!$J$6:$J$505,Transaksi!$O$6:$O$505,C15)) -> 0 | J15: =IF(C15="","",SUMIFS(Transaksi!$K$6:$K$505,Transaksi!$O$6:$O$505,C15)) -> 500000 | K15: =IF(C15="","",I15-J15) -> -500000 | L15: =IF(C15="","",IF(N(H15)=0,IF(J15>0,1.01,0),J15/H15)) -> 0.83333333 | M15: =IF(C15="","",COUNTIF(Transaksi!$O$6:$O$505,C15)) -> 1 | N15: =IF(C15="","",IF(OR(D15="",E15=""),"-",IF(E15<Pengaturan!$C$14,"Selesai",IF(D15>Pengaturan!$C$14,"Direncanakan","Berjalan")))) -> Selesai | O15: =IF(C15="","",IF(L15>1,"Melebihi",IF(L15>=Pengaturan!$C$15,"Waspada","Aman"))) -> Waspada
B16: =IF(C16="","",ROW()-8) -> 8 | C16: Seminar Akhir Tahun | D16: 46368 | E16: 46368 | F16: Jember | G16: Ketua Panitia | H16: 8000000 | I16: =IF(C16="","",SUMIFS(Transaksi!$J$6:$J$505,Transaksi!$O$6:$O$505,C16)) -> 0 | J16: =IF(C16="","",SUMIFS(Transaksi!$K$6:$K$505,Transaksi!$O$6:$O$505,C16)) -> 250000 | K16: =IF(C16="","",I16-J16) -> -250000 | L16: =IF(C16="","",IF(N(H16)=0,IF(J16>0,1.01,0),J16/H16)) -> 0.03125 | M16: =IF(C16="","",COUNTIF(Transaksi!$O$6:$O$505,C16)) -> 1 | N16: =IF(C16="","",IF(OR(D16="",E16=""),"-",IF(E16<Pengaturan!$C$14,"Selesai",IF(D16>Pengaturan!$C$14,"Direncanakan","Berjalan")))) -> Direncanakan | O16: =IF(C16="","",IF(L16>1,"Melebihi",IF(L16>=Pengaturan!$C$15,"Waspada","Aman"))) -> Aman
B17: =IF(C17="","",ROW()-8) | I17: =IF(C17="","",SUMIFS(Transaksi!$J$6:$J$505,Transaksi!$O$6:$O$505,C17)) | J17: =IF(C17="","",SUMIFS(Transaksi!$K$6:$K$505,Transaksi!$O$6:$O$505,C17)) | K17: =IF(C17="","",I17-J17) | L17: =IF(C17="","",IF(N(H17)=0,IF(J17>0,1.01,0),J17/H17)) | M17: =IF(C17="","",COUNTIF(Transaksi!$O$6:$O$505,C17)) | N17: =IF(C17="","",IF(OR(D17="",E17=""),"-",IF(E17<Pengaturan!$C$14,"Selesai",IF(D17>Pengaturan!$C$14,"Direncanakan","Berjalan")))) | O17: =IF(C17="","",IF(L17>1,"Melebihi",IF(L17>=Pengaturan!$C$15,"Waspada","Aman")))
B18: =IF(C18="","",ROW()-8) | I18: =IF(C18="","",SUMIFS(Transaksi!$J$6:$J$505,Transaksi!$O$6:$O$505,C18)) | J18: =IF(C18="","",SUMIFS(Transaksi!$K$6:$K$505,Transaksi!$O$6:$O$505,C18)) | K18: =IF(C18="","",I18-J18) | L18: =IF(C18="","",IF(N(H18)=0,IF(J18>0,1.01,0),J18/H18)) | M18: =IF(C18="","",COUNTIF(Transaksi!$O$6:$O$505,C18)) | N18: =IF(C18="","",IF(OR(D18="",E18=""),"-",IF(E18<Pengaturan!$C$14,"Selesai",IF(D18>Pengaturan!$C$14,"Direncanakan","Berjalan")))) | O18: =IF(C18="","",IF(L18>1,"Melebihi",IF(L18>=Pengaturan!$C$15,"Waspada","Aman")))
B19: =IF(C19="","",ROW()-8) | I19: =IF(C19="","",SUMIFS(Transaksi!$J$6:$J$505,Transaksi!$O$6:$O$505,C19)) | J19: =IF(C19="","",SUMIFS(Transaksi!$K$6:$K$505,Transaksi!$O$6:$O$505,C19)) | K19: =IF(C19="","",I19-J19) | L19: =IF(C19="","",IF(N(H19)=0,IF(J19>0,1.01,0),J19/H19)) | M19: =IF(C19="","",COUNTIF(Transaksi!$O$6:$O$505,C19)) | N19: =IF(C19="","",IF(OR(D19="",E19=""),"-",IF(E19<Pengaturan!$C$14,"Selesai",IF(D19>Pengaturan!$C$14,"Direncanakan","Berjalan")))) | O19: =IF(C19="","",IF(L19>1,"Melebihi",IF(L19>=Pengaturan!$C$15,"Waspada","Aman")))
B20: =IF(C20="","",ROW()-8) | I20: =IF(C20="","",SUMIFS(Transaksi!$J$6:$J$505,Transaksi!$O$6:$O$505,C20)) | J20: =IF(C20="","",SUMIFS(Transaksi!$K$6:$K$505,Transaksi!$O$6:$O$505,C20)) | K20: =IF(C20="","",I20-J20) | L20: =IF(C20="","",IF(N(H20)=0,IF(J20>0,1.01,0),J20/H20)) | M20: =IF(C20="","",COUNTIF(Transaksi!$O$6:$O$505,C20)) | N20: =IF(C20="","",IF(OR(D20="",E20=""),"-",IF(E20<Pengaturan!$C$14,"Selesai",IF(D20>Pengaturan!$C$14,"Direncanakan","Berjalan")))) | O20: =IF(C20="","",IF(L20>1,"Melebihi",IF(L20>=Pengaturan!$C$15,"Waspada","Aman")))
B21: =IF(C21="","",ROW()-8) | I21: =IF(C21="","",SUMIFS(Transaksi!$J$6:$J$505,Transaksi!$O$6:$O$505,C21)) | J21: =IF(C21="","",SUMIFS(Transaksi!$K$6:$K$505,Transaksi!$O$6:$O$505,C21)) | K21: =IF(C21="","",I21-J21) | L21: =IF(C21="","",IF(N(H21)=0,IF(J21>0,1.01,0),J21/H21)) | M21: =IF(C21="","",COUNTIF(Transaksi!$O$6:$O$505,C21)) | N21: =IF(C21="","",IF(OR(D21="",E21=""),"-",IF(E21<Pengaturan!$C$14,"Selesai",IF(D21>Pengaturan!$C$14,"Direncanakan","Berjalan")))) | O21: =IF(C21="","",IF(L21>1,"Melebihi",IF(L21>=Pengaturan!$C$15,"Waspada","Aman")))
B22: =IF(C22="","",ROW()-8) | I22: =IF(C22="","",SUMIFS(Transaksi!$J$6:$J$505,Transaksi!$O$6:$O$505,C22)) | J22: =IF(C22="","",SUMIFS(Transaksi!$K$6:$K$505,Transaksi!$O$6:$O$505,C22)) | K22: =IF(C22="","",I22-J22) | L22: =IF(C22="","",IF(N(H22)=0,IF(J22>0,1.01,0),J22/H22)) | M22: =IF(C22="","",COUNTIF(Transaksi!$O$6:$O$505,C22)) | N22: =IF(C22="","",IF(OR(D22="",E22=""),"-",IF(E22<Pengaturan!$C$14,"Selesai",IF(D22>Pengaturan!$C$14,"Direncanakan","Berjalan")))) | O22: =IF(C22="","",IF(L22>1,"Melebihi",IF(L22>=Pengaturan!$C$15,"Waspada","Aman")))
B23: =IF(C23="","",ROW()-8) | I23: =IF(C23="","",SUMIFS(Transaksi!$J$6:$J$505,Transaksi!$O$6:$O$505,C23)) | J23: =IF(C23="","",SUMIFS(Transaksi!$K$6:$K$505,Transaksi!$O$6:$O$505,C23)) | K23: =IF(C23="","",I23-J23) | L23: =IF(C23="","",IF(N(H23)=0,IF(J23>0,1.01,0),J23/H23)) | M23: =IF(C23="","",COUNTIF(Transaksi!$O$6:$O$505,C23)) | N23: =IF(C23="","",IF(OR(D23="",E23=""),"-",IF(E23<Pengaturan!$C$14,"Selesai",IF(D23>Pengaturan!$C$14,"Direncanakan","Berjalan")))) | O23: =IF(C23="","",IF(L23>1,"Melebihi",IF(L23>=Pengaturan!$C$15,"Waspada","Aman")))
B24: =IF(C24="","",ROW()-8) | I24: =IF(C24="","",SUMIFS(Transaksi!$J$6:$J$505,Transaksi!$O$6:$O$505,C24)) | J24: =IF(C24="","",SUMIFS(Transaksi!$K$6:$K$505,Transaksi!$O$6:$O$505,C24)) | K24: =IF(C24="","",I24-J24) | L24: =IF(C24="","",IF(N(H24)=0,IF(J24>0,1.01,0),J24/H24)) | M24: =IF(C24="","",COUNTIF(Transaksi!$O$6:$O$505,C24)) | N24: =IF(C24="","",IF(OR(D24="",E24=""),"-",IF(E24<Pengaturan!$C$14,"Selesai",IF(D24>Pengaturan!$C$14,"Direncanakan","Berjalan")))) | O24: =IF(C24="","",IF(L24>1,"Melebihi",IF(L24>=Pengaturan!$C$15,"Waspada","Aman")))
B25: =IF(C25="","",ROW()-8) | I25: =IF(C25="","",SUMIFS(Transaksi!$J$6:$J$505,Transaksi!$O$6:$O$505,C25)) | J25: =IF(C25="","",SUMIFS(Transaksi!$K$6:$K$505,Transaksi!$O$6:$O$505,C25)) | K25: =IF(C25="","",I25-J25) | L25: =IF(C25="","",IF(N(H25)=0,IF(J25>0,1.01,0),J25/H25)) | M25: =IF(C25="","",COUNTIF(Transaksi!$O$6:$O$505,C25)) | N25: =IF(C25="","",IF(OR(D25="",E25=""),"-",IF(E25<Pengaturan!$C$14,"Selesai",IF(D25>Pengaturan!$C$14,"Direncanakan","Berjalan")))) | O25: =IF(C25="","",IF(L25>1,"Melebihi",IF(L25>=Pengaturan!$C$15,"Waspada","Aman")))
B26: =IF(C26="","",ROW()-8) | I26: =IF(C26="","",SUMIFS(Transaksi!$J$6:$J$505,Transaksi!$O$6:$O$505,C26)) | J26: =IF(C26="","",SUMIFS(Transaksi!$K$6:$K$505,Transaksi!$O$6:$O$505,C26)) | K26: =IF(C26="","",I26-J26) | L26: =IF(C26="","",IF(N(H26)=0,IF(J26>0,1.01,0),J26/H26)) | M26: =IF(C26="","",COUNTIF(Transaksi!$O$6:$O$505,C26)) | N26: =IF(C26="","",IF(OR(D26="",E26=""),"-",IF(E26<Pengaturan!$C$14,"Selesai",IF(D26>Pengaturan!$C$14,"Direncanakan","Berjalan")))) | O26: =IF(C26="","",IF(L26>1,"Melebihi",IF(L26>=Pengaturan!$C$15,"Waspada","Aman")))
B27: =IF(C27="","",ROW()-8) | I27: =IF(C27="","",SUMIFS(Transaksi!$J$6:$J$505,Transaksi!$O$6:$O$505,C27)) | J27: =IF(C27="","",SUMIFS(Transaksi!$K$6:$K$505,Transaksi!$O$6:$O$505,C27)) | K27: =IF(C27="","",I27-J27) | L27: =IF(C27="","",IF(N(H27)=0,IF(J27>0,1.01,0),J27/H27)) | M27: =IF(C27="","",COUNTIF(Transaksi!$O$6:$O$505,C27)) | N27: =IF(C27="","",IF(OR(D27="",E27=""),"-",IF(E27<Pengaturan!$C$14,"Selesai",IF(D27>Pengaturan!$C$14,"Direncanakan","Berjalan")))) | O27: =IF(C27="","",IF(L27>1,"Melebihi",IF(L27>=Pengaturan!$C$15,"Waspada","Aman")))
B28: =IF(C28="","",ROW()-8) | I28: =IF(C28="","",SUMIFS(Transaksi!$J$6:$J$505,Transaksi!$O$6:$O$505,C28)) | J28: =IF(C28="","",SUMIFS(Transaksi!$K$6:$K$505,Transaksi!$O$6:$O$505,C28)) | K28: =IF(C28="","",I28-J28) | L28: =IF(C28="","",IF(N(H28)=0,IF(J28>0,1.01,0),J28/H28)) | M28: =IF(C28="","",COUNTIF(Transaksi!$O$6:$O$505,C28)) | N28: =IF(C28="","",IF(OR(D28="",E28=""),"-",IF(E28<Pengaturan!$C$14,"Selesai",IF(D28>Pengaturan!$C$14,"Direncanakan","Berjalan")))) | O28: =IF(C28="","",IF(L28>1,"Melebihi",IF(L28>=Pengaturan!$C$15,"Waspada","Aman")))
B29: TOTAL SELURUH EVENT | H29: =SUM(H9:H28) -> 28300000 | I29: =SUM(I9:I28) -> 20700000 | J29: =SUM(J9:J28) -> 16150000 | K29: =SUM(K9:K28) -> 4550000 | L29: =IF(H29=0,0,J29/H29) -> 0.57067138 | M29: =SUM(M9:M28) -> 16
B30: Di luar event (operasional / umum) | I30: =SUM(Transaksi!$J$6:$J$505)-I29 -> 143000 | J30: =SUM(Transaksi!$K$6:$K$505)-J29 -> 14380000 | K30: =I30-J30 -> -14237000 | M30: =COUNT(Transaksi!$C$6:$C$505)-M29 -> 23
B31: TOTAL KESELURUHAN (sama dengan sheet Transaksi) | I31: =I29+I30 -> 20843000 | J31: =J29+J30 -> 30530000 | K31: =K29+K30 -> -9687000 | M31: =M29+M30 -> 39

Sheet Aset
B1: DATA KEUANGAN HAPIA JEMBER
B2: ="DAFTAR ASET / INVENTARIS — penyusutan garis lurus s.d. tanggal laporan (lihat Pengaturan) • Tahun Buku "&Pengaturan!$C$6 -> DAFTAR ASET / INVENTARIS — penyusutan garis lurus s.d. tanggal laporan (lihat Pengaturan) • Tahun Buku 2026
B5: No | C5: Kode | D5: Nama Aset | E5: Kategori | F5: Tgl Perolehan | G5: Jumlah | H5: Harga Satuan (Rp) | I5: Nilai Perolehan (Rp) | J5: Umur (Thn) | K5: Penyusutan / Thn | L5: Akumulasi Penyusutan | M5: Nilai Buku (Rp) | N5: Kondisi | O5: Lokasi / Keterangan
B6: =IF(D6="","",ROW()-5) -> 1 | C6: AST-001 | D6: Laptop Sekretariat | E6: Elektronik | F6: 45717 | G6: 1 | H6: 6500000 | I6: =IF(D6="","",N(G6)*N(H6)) -> 6500000 | J6: 4 | K6: =IF(D6="","",IF(N(J6)>0,I6/J6,0)) -> 1625000 | L6: =IF(D6="","",IF(F6="",0,MIN(I6,K6*MAX(0,(YEAR(Pengaturan!$C$14)-YEAR(F6))*12+MONTH(Pengaturan!$C$14)-MONTH(F6))/12))) -> 2572916.7 | M6: =IF(D6="","",I6-L6) -> 3927083.3 | N6: Baik | O6: Sekretariat
B7: =IF(D7="","",ROW()-5) -> 2 | C7: AST-002 | D7: Meja Rapat | E7: Furnitur | F7: 45726 | G7: 2 | H7: 750000 | I7: =IF(D7="","",N(G7)*N(H7)) -> 1500000 | J7: 5 | K7: =IF(D7="","",IF(N(J7)>0,I7/J7,0)) -> 300000 | L7: =IF(D7="","",IF(F7="",0,MIN(I7,K7*MAX(0,(YEAR(Pengaturan!$C$14)-YEAR(F7))*12+MONTH(Pengaturan!$C$14)-MONTH(F7))/12))) -> 475000 | M7: =IF(D7="","",I7-L7) -> 1025000 | N7: Baik | O7: Sekretariat
B8: =IF(D8="","",ROW()-5) -> 3 | C8: AST-003 | D8: Lemari Arsip | E8: Furnitur | F8: 45672 | G8: 1 | H8: 1200000 | I8: =IF(D8="","",N(G8)*N(H8)) -> 1200000 | J8: 8 | K8: =IF(D8="","",IF(N(J8)>0,I8/J8,0)) -> 150000 | L8: =IF(D8="","",IF(F8="",0,MIN(I8,K8*MAX(0,(YEAR(Pengaturan!$C$14)-YEAR(F8))*12+MONTH(Pengaturan!$C$14)-MONTH(F8))/12))) -> 262500 | M8: =IF(D8="","",I8-L8) -> 937500 | N8: Baik | O8: Sekretariat
B9: =IF(D9="","",ROW()-5) -> 4 | C9: AST-004 | D9: Sound System | E9: Elektronik | F9: 45521 | G9: 1 | H9: 3000000 | I9: =IF(D9="","",N(G9)*N(H9)) -> 3000000 | J9: 5 | K9: =IF(D9="","",IF(N(J9)>0,I9/J9,0)) -> 600000 | L9: =IF(D9="","",IF(F9="",0,MIN(I9,K9*MAX(0,(YEAR(Pengaturan!$C$14)-YEAR(F9))*12+MONTH(Pengaturan!$C$14)-MONTH(F9))/12))) -> 1300000 | M9: =IF(D9="","",I9-L9) -> 1700000 | N9: Cukup | O9: Gudang
B10: =IF(D10="","",ROW()-5) -> 5 | C10: AST-005 | D10: Proyektor | E10: Elektronik | F10: 46181 | G10: 1 | H10: 4500000 | I10: =IF(D10="","",N(G10)*N(H10)) -> 4500000 | J10: 4 | K10: =IF(D10="","",IF(N(J10)>0,I10/J10,0)) -> 1125000 | L10: =IF(D10="","",IF(F10="",0,MIN(I10,K10*MAX(0,(YEAR(Pengaturan!$C$14)-YEAR(F10))*12+MONTH(Pengaturan!$C$14)-MONTH(F10))/12))) -> 375000 | M10: =IF(D10="","",I10-L10) -> 4125000 | N10: Baik | O10: Sekretariat
